package tiatech.common.metatileentities.multi;

import gregtech.api.gui.GuiTextures;
import gregtech.api.gui.ModularUI;
import gregtech.api.gui.widgets.LabelWidget;
import gregtech.api.gui.widgets.ProgressWidget;
import gregtech.api.gui.widgets.RecipeProgressWidget;
import gregtech.api.metatileentity.MetaTileEntity;
import gregtech.api.metatileentity.interfaces.IGregTechTileEntity;
import gregtech.api.metatileentity.multiblock.IMultiblockPart;
import gregtech.api.metatileentity.multiblock.RecipeMapPrimitiveMultiblockController;
import gregtech.api.pattern.BlockPattern;
import gregtech.api.pattern.FactoryBlockPattern;
import gregtech.api.recipes.RecipeMaps;
import gregtech.api.unification.material.Materials;
import gregtech.client.particle.VanillaParticleEffects;
import gregtech.client.renderer.ICubeRenderer;
import gregtech.client.renderer.texture.Textures;
import gregtech.common.blocks.BlockMetalCasing;
import gregtech.common.blocks.MetaBlocks;

import gregtech.common.metatileentities.MetaTileEntities;
import net.minecraft.block.state.IBlockState;
import net.minecraft.client.resources.I18n;
import net.minecraft.entity.player.EntityPlayer;
import net.minecraft.init.Blocks;
import net.minecraft.item.ItemStack;
import net.minecraft.util.EnumParticleTypes;
import net.minecraft.util.ResourceLocation;
import net.minecraft.world.World;
import net.minecraftforge.fml.relauncher.Side;
import net.minecraftforge.fml.relauncher.SideOnly;

import codechicken.lib.render.CCRenderState;
import codechicken.lib.render.pipeline.IVertexOperation;
import codechicken.lib.vec.Matrix4;
import org.jetbrains.annotations.NotNull;
import org.jetbrains.annotations.Nullable;
import tiatech.api.metatileentity.TiaTechRecipeMapPrimitiveMultiblockController;

import java.util.List;

public class MetaTileEntityMegaPrimitiveBlastFurnace extends TiaTechRecipeMapPrimitiveMultiblockController {

    private static final int PARALLEL_LIMIT = 256;

    public MetaTileEntityMegaPrimitiveBlastFurnace(ResourceLocation metaTileEntityId) {
        super(metaTileEntityId, RecipeMaps.PRIMITIVE_BLAST_FURNACE_RECIPES);
        this.recipeMapWorkable.setParallelLimit(PARALLEL_LIMIT);
    }

    @Override
    public MetaTileEntity createMetaTileEntity(IGregTechTileEntity tileEntity) {
        return new MetaTileEntityMegaPrimitiveBlastFurnace(metaTileEntityId);
    }

    @Override
    @NotNull
    protected BlockPattern createStructurePattern() {
        return FactoryBlockPattern.start()
                .aisle( " NNN   NNN             NNN   NNN ",
                        "                                 ",
                        "                                 ",
                        "                                 ",
                        " NNN   NNN             NNN   NNN ",
                        "                                 ",
                        "                                 ",
                        "                                 ",
                        "                                 ",
                        "                                 ",
                        " NNN   NNN             NNN   NNN ",
                        "                                 ",
                        "                                 ",
                        "                                 ",
                        " NNN   NNN   N     N   NNN   NNN ",
                        "         N   N     N   N         ",
                        "         N   N     N   N         ",
                        "                                 ",
                        "                                 ",
                        "                                 ",
                        "         N   N     N   N         ",
                        "         N   N     N   N         ",
                        "         N   N     N   N         ",
                        "                                 ")
                .aisle( "NBBBN NBBBN    N N    NBBBN NBBBN",
                        " CCC   CCC             CCC   CCC ",
                        " CCC   CCC             CCC   CCC ",
                        " CCC   CCC             CCC   CCC ",
                        "NBBBN NBBBN           NBBBN NBBBN",
                        "  N     N               N     N  ",
                        "  N     N               N     N  ",
                        "                                 ",
                        "  N     N               N     N  ",
                        "  N     N               N     N  ",
                        "NBBBN NBBBN           NBBBN NBBBN",
                        " CCC   CCC             CCC   CCC ",
                        " CCC   CCC             CCC   CCC ",
                        " CCC   CCC   N     N   CCC   CCC ",
                        "NBBBN NBBNCCCB     BCCCNBBN NBBBN",
                        "         BCCCB     BCCCB         ",
                        "         BCCCB     BCCCB         ",
                        "         N   N     N   N         ",
                        "                                 ",
                        "         N   N     N   N         ",
                        "         BCCCB     BCCCB         ",
                        "         BCCCB     BCCCB         ",
                        "         BCCCB     BCCCB         ",
                        "         N   N     N   N         ")
                .aisle( "NBBBN NBBBNNNNNXNXNNNNNBBBN NBBBN",
                        " CBC   CBC             CBC   CBC ",
                        " CBC   CBC             CBC   CBC ",
                        " CBC   CBC             CBC   CBC ",
                        "NBBBN NBBBN           NBBBN NBBBN",
                        " NNN   NNN             NNN   NNN ",
                        " NNN   NNN             NNN   NNN ",
                        "  X     X               X     X  ",
                        " NNN   NNN             NNN   NNN ",
                        " NNN   NNN             NNN   NNN ",
                        "NBBBN NBBBN           NBBBN NBBBN",
                        " CBC   CBC             CBC   CBC ",
                        " CBC   CBC             CBC   CBC ",
                        " CBC   CBC   N     N   CBC   CBC ",
                        "NBBBN NBBNCCCB     BCCCNBBN NBBBN",
                        "  N     XBBBBBNNXNNBBBBBX     N  ",
                        "  N      BCCCB     BCCCB      N  ",
                        "  N      N   N     N   N      N  ",
                        "   X                         X   ",
                        "   X     N   N     N   N     X   ",
                        "    XX   BCCCB     BCCCB   XX    ",
                        "      NNNBBBBBNNXNNBBBBBNNN      ",
                        "         BCCCB     BCCCB         ",
                        "         N   N     N   N         ")
                .aisle( "NBBBNNNBBBN    NBN    NBBBNNNBBBN",
                        " CCCCCCCCC             CCCCCCCCC ",
                        " CCCCCCCCC             CCCCCCCCC ",
                        " CCCCCCCCC             CCCCCCCCC ",
                        "NBBBNNNBBBN           NBBBNNNBBBN",
                        "  N     N               N     N  ",
                        "  N     N               N     N  ",
                        "                                 ",
                        "  N     N               N     N  ",
                        "  N     N               N     N  ",
                        "NBBBNNNBBBN           NBBBNNNBBBN",
                        " CCCCCCCCC             CCCCCCCCC ",
                        " CCCCCCCCC             CCCCCCCCC ",
                        " CCCCCCCCC   N     N   CCCCCCCCC ",
                        "NBBBNNNBBNCCCB     BCCCNBBNNNBBBN",
                        "         BCCCB     BCCCB         ",
                        "         BCCCB     BCCCB         ",
                        "         NCCCN     NCCCN         ",
                        "  X      NCCCN     NCCCN      X  ",
                        "  X      NCCCN     NCCCN      X  ",
                        "         BCCCB     BCCCB         ",
                        "    XX   BCCCB     BCCCB   XX    ",
                        "         BCCCB     BCCCB         ",
                        "         N   N     N   N         ")
                .aisle( " NNN   NNN     NBN     NNN   NNN ",
                        "   C   C                 C   C   ",
                        "   C   C                 C   C   ",
                        "   C   C                 C   C   ",
                        " NNN   NNN             NNN   NNN ",
                        "                                 ",
                        "                                 ",
                        "                                 ",
                        "                                 ",
                        "                                 ",
                        " NNN   NNN             NNN   NNN ",
                        "   C   C                 C   C   ",
                        "   C   C                 C   C   ",
                        "   C   C                 C   C   ",
                        " NNN   NN    N     N    NN   NNN ",
                        "         N   N     N   N         ",
                        "         NCCCN     NCCCN         ",
                        "                                 ",
                        "                                 ",
                        "                                 ",
                        "  X      NCCCN     NCCCN      X  ",
                        "   X     N   N     N   N     X   ",
                        "         N   N     N   N         ",
                        "                                 ")
                .aisle( "   N   N       NBN       N   N   ",
                        "   C   C                 C   C   ",
                        "   C   C                 C   C   ",
                        "   C   C                 C   C   ",
                        "   N   N                 N   N   ",
                        "                                 ",
                        "                                 ",
                        "                                 ",
                        "                                 ",
                        "                                 ",
                        "   N   N                 N   N   ",
                        "   C   C                 C   C   ",
                        "   C   C                 C   C   ",
                        "   C   C                 C   C   ",
                        "   N   N                 N   N   ",
                        "                                 ",
                        "         NCCCN     NCCCN         ",
                        "                                 ",
                        "                                 ",
                        "                                 ",
                        "  X      NCCCN     NCCCN      X  ",
                        "   X                         X   ",
                        "                                 ",
                        "                                 ")
                .aisle( " NNN   NNN     NBN     NNN   NNN ",
                        "   C   C                 C   C   ",
                        "   C   C                 C   C   ",
                        "   C   C                 C   C   ",
                        " NNN   NNN             NNN   NNN ",
                        "                                 ",
                        "                                 ",
                        "                                 ",
                        "                                 ",
                        "                                 ",
                        " NNN   NNN             NNN   NNN ",
                        "   C   C                 C   C   ",
                        "   C   C                 C   C   ",
                        "   C   C                 C   C   ",
                        " NNN   NN    N     N    NN   NNN ",
                        "         N   N     N   N         ",
                        "         NCCCN     NCCCN         ",
                        "                                 ",
                        "                                 ",
                        "                                 ",
                        "         NCCCN     NCCCN         ",
                        "  N      N   N     N   N      N  ",
                        "         N   N     N   N         ",
                        "                                 ")
                .aisle( "NBBBNNNBBBN    NBN    NBBBNNNBBBN",
                        " CCCCCCCCC             CCCCCCCCC ",
                        " CCCCCCCCC             CCCCCCCCC ",
                        " CCCCCCCCC             CCCCCCCCC ",
                        "NBBBNNNBBBN           NBBBNNNBBBN",
                        "  N     N               N     N  ",
                        "  N     N               N     N  ",
                        "                                 ",
                        "  N     N               N     N  ",
                        "  N     N               N     N  ",
                        "NBBBNNNBBBN           NBBBNNNBBBN",
                        " CCCCCCCCC             CCCCCCCCC ",
                        " CCCCCCCCC             CCCCCCCCC ",
                        " CCCCCCCCC   N     N   CCCCCCCCC ",
                        "NBBBNNNBBNCCCB     BCCCNBBNNNBBBN",
                        "         BCCCB     BCCCB         ",
                        "         BCCCB     BCCCB         ",
                        "         NCCCN     NCCCN         ",
                        "         NCCCN     NCCCN         ",
                        "         NCCCN     NCCCN         ",
                        "         BCCCB     BCCCB         ",
                        "  N      BCCCB     BCCCB      N  ",
                        "         BCCCB     BCCCB         ",
                        "         N   N     N   N         ")
                .aisle( "NBBBN NBBBNNNNNXNXNNNNNBBBN NBBBN",
                        " CBC   CBC             CBC   CBC ",
                        " CBC   CBC             CBC   CBC ",
                        " CBC   CBC             CBC   CBC ",
                        "NBBBN NBBBN           NBBBN NBBBN",
                        " NNN   NNN             NNN   NNN ",
                        " NNN   NNN             NNN   NNN ",
                        "  X     X               X     X  ",
                        " NNN   NNN             NNN   NNN ",
                        " NNN   NNN             NNN   NNN ",
                        "NBBBN NBBBN           NBBBN NBBBN",
                        " CBC   CBC             CBC   CBC ",
                        " CBC   CBC             CBC   CBC ",
                        " CBC   CBC   N     N   CBC   CBC ",
                        "NBBBN NBBNCCCB     BCCCNBBN NBBBN",
                        "  X     XBBBBBNNXNNBBBBBX     X  ",
                        "         BCCCB     BCCCB         ",
                        "         N   N     N   N         ",
                        "                                 ",
                        "         N   N     N   N         ",
                        "         BCCCB     BCCCB         ",
                        "  N     XBBBBBNNXNNBBBBBX     N  ",
                        "         BCCCB     BCCCB         ",
                        "         N   N     N   N         ")
                .aisle( "NBBBN NBBBN    NBN    NBBBN NBBBN",
                        " CCC   CCC             CCC   CCC ",
                        " CCC   CCC             CCC   CCC ",
                        " CCC   CCC             CCC   CCC ",
                        "NBBBN NBBBN           NBBBN NBBBN",
                        "  N     N               N     N  ",
                        "  N     N               N     N  ",
                        "                                 ",
                        "  N     N               N     N  ",
                        "  N     N               N     N  ",
                        "NBBBN NBBBN           NBBBN NBBBN",
                        " CCC   CCC             CCC   CCC ",
                        " CCC   CCC             CCC   CCC ",
                        " CCC   CCC   N     N   CCC   CCC ",
                        "NNNN   NNNCCCB     BCCCNNN   NNNN",
                        "NBBBN NBBNCCCB     BCCCNBBN NBBBN",
                        "NBBBNNNBBNCCCB     BCCCNBBNNNBBBN",
                        " NNN   NNN   N     N   NNN   NNN ",
                        "   N   N                 N   N   ",
                        " NNN   NNN   N     N   NNN   NNN ",
                        "NBBBNNNBBNCCCB     BCCCNBBNNNBBBN",
                        "NBBBN NBBNCCCB     BCCCNBBN NBBBN",
                        "NBBBN NBBNCCCB     BCCCNBBN NBBBN",
                        " NNN   NNN   N     N   NNN   NNN ")
                .aisle( " NNN   NNN     NBN     NNN   NNN ",
                        "                                 ",
                        "                                 ",
                        "                                 ",
                        " NNN   NNN             NNN   NNN ",
                        "                                 ",
                        "                                 ",
                        "                                 ",
                        "                                 ",
                        "                                 ",
                        " NNN   NNN             NNN   NNN ",
                        "                                 ",
                        "                                 ",
                        "                                 ",
                        " CCC   CCC   N     N   CCC   CCC ",
                        " CBC   CBC   N     N   CBC   CBC ",
                        " CCCCCCCCC   N     N   CCCCCCCCC ",
                        "   C   C                 C   C   ",
                        "   C   C                 C   C   ",
                        "   C   C                 C   C   ",
                        " CCCCCCCCC   N     N   CCCCCCCCC ",
                        " CBC   CBC   N     N   CBC   CBC ",
                        " CCC   CCC   N     N   CCC   CCC ",
                        "                                 ")
                .aisle( "  N     N      NBN      N     N  ",
                        "                                 ",
                        "                                 ",
                        "                                 ",
                        "                                 ",
                        "                                 ",
                        "                                 ",
                        "                                 ",
                        "                                 ",
                        "                                 ",
                        "                                 ",
                        "                                 ",
                        "                                 ",
                        "                                 ",
                        " CCC   CCC             CCC   CCC ",
                        " CBC   CBC             CBC   CBC ",
                        " CCCCCCCCC             CCCCCCCCC ",
                        "   C   C                 C   C   ",
                        "   C   C                 C   C   ",
                        "   C   C                 C   C   ",
                        " CCCCCCCCC             CCCCCCCCC ",
                        " CBC   CBC             CBC   CBC ",
                        " CCC   CCC             CCC   CCC ",
                        "                                 ")
                .aisle( "  N     N      NBN      N     N  ",
                        "                                 ",
                        "                                 ",
                        "                                 ",
                        "                                 ",
                        "                                 ",
                        "                                 ",
                        "                                 ",
                        "                                 ",
                        "                                 ",
                        "                                 ",
                        "                                 ",
                        "                                 ",
                        "                                 ",
                        " CCC   CCC             CCC   CCC ",
                        " CBC   CBC             CBC   CBC ",
                        " CCCCCCCCC             CCCCCCCCC ",
                        "   C   C                 C   C   ",
                        "   C   C                 C   C   ",
                        "   C   C                 C   C   ",
                        " CCCCCCCCC             CCCCCCCCC ",
                        " CBC   CBC             CBC   CBC ",
                        " CCC   CCC             CCC   CCC ",
                        "                                 ")
                .aisle( "  N     N     NXNXN     N     N  ",
                        "                                 ",
                        "                                 ",
                        "                                 ",
                        "                                 ",
                        "                                 ",
                        "                                 ",
                        "                                 ",
                        "                                 ",
                        "                                 ",
                        "                                 ",
                        "                                 ",
                        "                                 ",
                        " NNN   NNN             NNN   NNN ",
                        "NBBBN NBBBN           NBBBN NBBBN",
                        "NBBBN NBBBN           NBBBN NBBBN",
                        "NBBBNNNBBBN           NBBBNNNBBBN",
                        " NNN   NNN             NNN   NNN ",
                        "   N   N                 N   N   ",
                        " NNN   NNN             NNN   NNN ",
                        "NBBBNNNBBBN           NBBBNNNBBBN",
                        "NBBBN NBBBN           NBBBN NBBBN",
                        "NBBBN NBBBN           NBBBN NBBBN",
                        " NNN   NNN             NNN   NNN ")
                .aisle( "  N     N    NBBBBBN    N     N  ",
                        "                                 ",
                        "                                 ",
                        "                                 ",
                        "                                 ",
                        "                                 ",
                        "                                 ",
                        "                                 ",
                        "                                 ",
                        "                                 ",
                        "                                 ",
                        "                                 ",
                        "                                 ",
                        "                                 ",
                        "                                 ",
                        "  N     N               N     N  ",
                        "                                 ",
                        "                                 ",
                        "                                 ",
                        "                                 ",
                        "                                 ",
                        "  N     N               N     N  ",
                        "                                 ",
                        "                                 ")
                .aisle( " NXNNNNNXNNNNXBBBBBXNNNNXNNNNNXN ",
                        "                N                ",
                        "                                 ",
                        "                                 ",
                        "                                 ",
                        "                                 ",
                        "                                 ",
                        "                                 ",
                        "                                 ",
                        "                                 ",
                        "                                 ",
                        "                                 ",
                        "                                 ",
                        "                                 ",
                        "                                 ",
                        "  N     N               N     N  ",
                        "                                 ",
                        "                                 ",
                        "                                 ",
                        "                                 ",
                        "                                 ",
                        "  N     N               N     N  ",
                        "                                 ",
                        "                                 ")
                .aisle( "  NBBBBBNBBBBNBBBBBNBBBBNBBBBBN  ",
                        "               NNN               ",
                        "                S                ",
                        "                                 ",
                        "                                 ",
                        "                                 ",
                        "                                 ",
                        "                                 ",
                        "                                 ",
                        "                                 ",
                        "                                 ",
                        "                                 ",
                        "                                 ",
                        "                                 ",
                        "                                 ",
                        "  X     X               X     X  ",
                        "                                 ",
                        "                                 ",
                        "                                 ",
                        "                                 ",
                        "                                 ",
                        "  X     X               X     X  ",
                        "                                 ",
                        "                                 ")
                .aisle( " NXNNNNNXNNNNXBBBBBXNNNNXNNNNNXN ",
                        "                N                ",
                        "                                 ",
                        "                                 ",
                        "                                 ",
                        "                                 ",
                        "                                 ",
                        "                                 ",
                        "                                 ",
                        "                                 ",
                        "                                 ",
                        "                                 ",
                        "                                 ",
                        "                                 ",
                        "                                 ",
                        "  N     N               N     N  ",
                        "                                 ",
                        "                                 ",
                        "                                 ",
                        "                                 ",
                        "                                 ",
                        "  N     N               N     N  ",
                        "                                 ",
                        "                                 ")
                .aisle( "  N     N    NBBBBBN    N     N  ",
                        "                                 ",
                        "                                 ",
                        "                                 ",
                        "                                 ",
                        "                                 ",
                        "                                 ",
                        "                                 ",
                        "                                 ",
                        "                                 ",
                        "                                 ",
                        "                                 ",
                        "                                 ",
                        "                                 ",
                        "                                 ",
                        "  N     N               N     N  ",
                        "                                 ",
                        "                                 ",
                        "                                 ",
                        "                                 ",
                        "                                 ",
                        "  N     N               N     N  ",
                        "                                 ",
                        "                                 ")
                .aisle( "  N     N     NXNXN     N     N  ",
                        "                                 ",
                        "                                 ",
                        "                                 ",
                        "                                 ",
                        "                                 ",
                        "                                 ",
                        "                                 ",
                        "                                 ",
                        "                                 ",
                        "                                 ",
                        "                                 ",
                        "                                 ",
                        " NNN   NNN             NNN   NNN ",
                        "NBBBN NBBBN           NBBBN NBBBN",
                        "NBBBN NBBBN           NBBBN NBBBN",
                        "NBBBNNNBBBN           NBBBNNNBBBN",
                        " NNN   NNN             NNN   NNN ",
                        "   N   N                 N   N   ",
                        " NNN   NNN             NNN   NNN ",
                        "NBBBNNNBBBN           NBBBNNNBBBN",
                        "NBBBN NBBBN           NBBBN NBBBN",
                        "NBBBN NBBBN           NBBBN NBBBN",
                        " NNN   NNN             NNN   NNN ")
                .aisle( "  N     N      NBN      N     N  ",
                        "                                 ",
                        "                                 ",
                        "                                 ",
                        "                                 ",
                        "                                 ",
                        "                                 ",
                        "                                 ",
                        "                                 ",
                        "                                 ",
                        "                                 ",
                        "                                 ",
                        "                                 ",
                        "                                 ",
                        " CCC   CCC             CCC   CCC ",
                        " CBC   CBC             CBC   CBC ",
                        " CCCCCCCCC             CCCCCCCCC ",
                        "   C   C                 C   C   ",
                        "   C   C                 C   C   ",
                        "   C   C                 C   C   ",
                        " CCCCCCCCC             CCCCCCCCC ",
                        " CBC   CBC             CBC   CBC ",
                        " CCC   CCC             CCC   CCC ",
                        "                                 ")
                .aisle( "  N     N      NBN      N     N  ",
                        "                                 ",
                        "                                 ",
                        "                                 ",
                        "                                 ",
                        "                                 ",
                        "                                 ",
                        "                                 ",
                        "                                 ",
                        "                                 ",
                        "                                 ",
                        "                                 ",
                        "                                 ",
                        "                                 ",
                        " CCC   CCC             CCC   CCC ",
                        " CBC   CBC             CBC   CBC ",
                        " CCCCCCCCC             CCCCCCCCC ",
                        "   C   C                 C   C   ",
                        "   C   C                 C   C   ",
                        "   C   C                 C   C   ",
                        " CCCCCCCCC             CCCCCCCCC ",
                        " CBC   CBC             CBC   CBC ",
                        " CCC   CCC             CCC   CCC ",
                        "                                 ")
                .aisle( " NNN   NNN     NBN     NNN   NNN ",
                        "                                 ",
                        "                                 ",
                        "                                 ",
                        " NNN   NNN             NNN   NNN ",
                        "                                 ",
                        "                                 ",
                        "                                 ",
                        "                                 ",
                        "                                 ",
                        " NNN   NNN             NNN   NNN ",
                        "                                 ",
                        "                                 ",
                        "                                 ",
                        " CCC   CCC   N     N   CCC   CCC ",
                        " CBC   CBC   N     N   CBC   CBC ",
                        " CCCCCCCCC   N     N   CCCCCCCCC ",
                        "   C   C                 C   C   ",
                        "   C   C                 C   C   ",
                        "   C   C                 C   C   ",
                        " CCCCCCCCC   N     N   CCCCCCCCC ",
                        " CBC   CBC   N     N   CBC   CBC ",
                        " CCC   CCC   N     N   CCC   CCC ",
                        "                                 ")
                .aisle( "NBBBN NBBBN    NBN    NBBBN NBBBN",
                        " CCC   CCC             CCC   CCC ",
                        " CCC   CCC             CCC   CCC ",
                        " CCC   CCC             CCC   CCC ",
                        "NBBBN NBBBN           NBBBN NBBBN",
                        "  N     N               N     N  ",
                        "  N     N               N     N  ",
                        "                                 ",
                        "  N     N               N     N  ",
                        "  N     N               N     N  ",
                        "NBBBN NBBBN           NBBBN NBBBN",
                        " CCC   CCC             CCC   CCC ",
                        " CCC   CCC             CCC   CCC ",
                        " CCC   CCC   N     N   CCC   CCC ",
                        "NNNN   NNNCCCB     BCCCNNN   NNNN",
                        "NBBBN NBBNCCCB     BCCCNBBN NBBBN",
                        "NBBBNNNBBNCCCB     BCCCNBBNNNBBBN",
                        " NNN   NNN   N     N   NNN   NNN ",
                        "   N   N                 N   N   ",
                        " NNN   NNN   N     N   NNN   NNN ",
                        "NBBBNNNBBNCCCB     BCCCNBBNNNBBBN",
                        "NBBBN NBBNCCCB     BCCCNBBN NBBBN",
                        "NBBBN NBBNCCCB     BCCCNBBN NBBBN",
                        " NNN   NNN   N     N   NNN   NNN ")
                .aisle( "NBBBN NBBBNNNNNXNXNNNNNBBBN NBBBN",
                        " CBC   CBC             CBC   CBC ",
                        " CBC   CBC             CBC   CBC ",
                        " CBC   CBC             CBC   CBC ",
                        "NBBBN NBBBN           NBBBN NBBBN",
                        " NNN   NNN             NNN   NNN ",
                        " NNN   NNN             NNN   NNN ",
                        "  X     X               X     X  ",
                        " NNN   NNN             NNN   NNN ",
                        " NNN   NNN             NNN   NNN ",
                        "NBBBN NBBBN           NBBBN NBBBN",
                        " CBC   CBC             CBC   CBC ",
                        " CBC   CBC             CBC   CBC ",
                        " CBC   CBC   N     N   CBC   CBC ",
                        "NBBBN NBBNCCCB     BCCCNBBN NBBBN",
                        "  X     XBBBBBNNXNNBBBBBX     X  ",
                        "         BCCCB     BCCCB         ",
                        "         N   N     N   N         ",
                        "                                 ",
                        "         N   N     N   N         ",
                        "         BCCCB     BCCCB         ",
                        "  N     XBBBBBNNXNNBBBBBX     N  ",
                        "         BCCCB     BCCCB         ",
                        "         N   N     N   N         ")
                .aisle( "NBBBNNNBBBN    NBN    NBBBNNNBBBN",
                        " CCCCCCCCC             CCCCCCCCC ",
                        " CCCCCCCCC             CCCCCCCCC ",
                        " CCCCCCCCC             CCCCCCCCC ",
                        "NBBBNNNBBBN           NBBBNNNBBBN",
                        "  N     N               N     N  ",
                        "  N     N               N     N  ",
                        "                                 ",
                        "  N     N               N     N  ",
                        "  N     N               N     N  ",
                        "NBBBNNNBBBN           NBBBNNNBBBN",
                        " CCCCCCCCC             CCCCCCCCC ",
                        " CCCCCCCCC             CCCCCCCCC ",
                        " CCCCCCCCC   N     N   CCCCCCCCC ",
                        "NBBBNNNBBNCCCB     BCCCNBBNNNBBBN",
                        "         BCCCB     BCCCB         ",
                        "         BCCCB     BCCCB         ",
                        "         NCCCN     NCCCN         ",
                        "         NCCCN     NCCCN         ",
                        "         NCCCN     NCCCN         ",
                        "         BCCCB     BCCCB         ",
                        "  N      BCCCB     BCCCB      N  ",
                        "         BCCCB     BCCCB         ",
                        "         N   N     N   N         ")
                .aisle( " NNN   NNN     NBN     NNN   NNN ",
                        "   C   C                 C   C   ",
                        "   C   C                 C   C   ",
                        "   C   C                 C   C   ",
                        " NNN   NNN             NNN   NNN ",
                        "                                 ",
                        "                                 ",
                        "                                 ",
                        "                                 ",
                        "                                 ",
                        " NNN   NNN             NNN   NNN ",
                        "   C   C                 C   C   ",
                        "   C   C                 C   C   ",
                        "   C   C                 C   C   ",
                        " NNN   NN    N     N    NN   NNN ",
                        "         N   N     N   N         ",
                        "         NCCCN     NCCCN         ",
                        "                                 ",
                        "                                 ",
                        "                                 ",
                        "         NCCCN     NCCCN         ",
                        "  N      N   N     N   N      N  ",
                        "         N   N     N   N         ",
                        "                                 ")
                .aisle( "   N   N       NBN       N   N   ",
                        "   C   C                 C   C   ",
                        "   C   C                 C   C   ",
                        "   C   C                 C   C   ",
                        "   N   N                 N   N   ",
                        "                                 ",
                        "                                 ",
                        "                                 ",
                        "                                 ",
                        "                                 ",
                        "   N   N                 N   N   ",
                        "   C   C                 C   C   ",
                        "   C   C                 C   C   ",
                        "   C   C                 C   C   ",
                        "   N   N                 N   N   ",
                        "                                 ",
                        "         NCCCN     NCCCN         ",
                        "                                 ",
                        "                                 ",
                        "                                 ",
                        "  X      NCCCN     NCCCN      X  ",
                        "   X                         X   ",
                        "                                 ",
                        "                                 ")
                .aisle( " NNN   NNN     NBN     NNN   NNN ",
                        "   C   C                 C   C   ",
                        "   C   C                 C   C   ",
                        "   C   C                 C   C   ",
                        " NNN   NNN             NNN   NNN ",
                        "                                 ",
                        "                                 ",
                        "                                 ",
                        "                                 ",
                        "                                 ",
                        " NNN   NNN             NNN   NNN ",
                        "   C   C                 C   C   ",
                        "   C   C                 C   C   ",
                        "   C   C                 C   C   ",
                        " NNN   NN    N     N    NN   NNN ",
                        "         N   N     N   N         ",
                        "         NCCCN     NCCCN         ",
                        "                                 ",
                        "                                 ",
                        "                                 ",
                        "  X      NCCCN     NCCCN      X  ",
                        "   X     N   N     N   N     X   ",
                        "         N   N     N   N         ",
                        "                                 ")
                .aisle( "NBBBNNNBBBN    NBN    NBBBNNNBBBN",
                        " CCCCCCCCC             CCCCCCCCC ",
                        " CCCCCCCCC             CCCCCCCCC ",
                        " CCCCCCCCC             CCCCCCCCC ",
                        "NBBBNNNBBBN           NBBBNNNBBBN",
                        "  N     N               N     N  ",
                        "  N     N               N     N  ",
                        "                                 ",
                        "  N     N               N     N  ",
                        "  N     N               N     N  ",
                        "NBBBNNNBBBN           NBBBNNNBBBN",
                        " CCCCCCCCC             CCCCCCCCC ",
                        " CCCCCCCCC             CCCCCCCCC ",
                        " CCCCCCCCC   N     N   CCCCCCCCC ",
                        "NBBBNNNBBNCCCB     BCCCNBBNNNBBBN",
                        "         BCCCB     BCCCB         ",
                        "         BCCCB     BCCCB         ",
                        "         NCCCN     NCCCN         ",
                        "  X      NCCCN     NCCCN      X  ",
                        "  X      NCCCN     NCCCN      X  ",
                        "         BCCCB     BCCCB         ",
                        "    XX   BCCCB     BCCCB   XX    ",
                        "         BCCCB     BCCCB         ",
                        "         N   N     N   N         ")
                .aisle( "NBBBN NBBBNNNNNXNXNNNNNBBBN NBBBN",
                        " CBC   CBC             CBC   CBC ",
                        " CBC   CBC             CBC   CBC ",
                        " CBC   CBC             CBC   CBC ",
                        "NBBBN NBBBN           NBBBN NBBBN",
                        " NNN   NNN             NNN   NNN ",
                        " NNN   NNN             NNN   NNN ",
                        "  X     X               X     X  ",
                        " NNN   NNN             NNN   NNN ",
                        " NNN   NNN             NNN   NNN ",
                        "NBBBN NBBBN           NBBBN NBBBN",
                        " CBC   CBC             CBC   CBC ",
                        " CBC   CBC             CBC   CBC ",
                        " CBC   CBC   N     N   CBC   CBC ",
                        "NBBBN NBBNCCCB     BCCCNBBN NBBBN",
                        "  N     XBBBBBNNXNNBBBBBX     N  ",
                        "  N      BCCCB     BCCCB      N  ",
                        "  N      N   N     N   N      N  ",
                        "   X                         X   ",
                        "   X     N   N     N   N     X   ",
                        "    XX   BCCCB     BCCCB   XX    ",
                        "      NNNBBBBBNNXNNBBBBBNNN      ",
                        "         BCCCB     BCCCB         ",
                        "         N   N     N   N         ")
                .aisle( "NBBBN NBBBN    N N    NBBBN NBBBN",
                        " CCC   CCC             CCC   CCC ",
                        " CCC   CCC             CCC   CCC ",
                        " CCC   CCC             CCC   CCC ",
                        "NBBBN NBBBN           NBBBN NBBBN",
                        "  N     N               N     N  ",
                        "  N     N               N     N  ",
                        "                                 ",
                        "  N     N               N     N  ",
                        "  N     N               N     N  ",
                        "NBBBN NBBBN           NBBBN NBBBN",
                        " CCC   CCC             CCC   CCC ",
                        " CCC   CCC             CCC   CCC ",
                        " CCC   CCC   N     N   CCC   CCC ",
                        "NBBBN NBBNCCCB     BCCCNBBN NBBBN",
                        "         BCCCB     BCCCB         ",
                        "         BCCCB     BCCCB         ",
                        "         N   N     N   N         ",
                        "                                 ",
                        "         N   N     N   N         ",
                        "         BCCCB     BCCCB         ",
                        "         BCCCB     BCCCB         ",
                        "         BCCCB     BCCCB         ",
                        "         N   N     N   N         ")
                .aisle( "NBBBN NBBBN    N N    NBBBN NBBBN",
                        " CCC   CCC             CCC   CCC ",
                        " CCC   CCC             CCC   CCC ",
                        " CCC   CCC             CCC   CCC ",
                        "NBBBN NBBBN           NBBBN NBBBN",
                        "  N     N               N     N  ",
                        "  N     N               N     N  ",
                        "                                 ",
                        "  N     N               N     N  ",
                        "  N     N               N     N  ",
                        "NBBBN NBBBN           NBBBN NBBBN",
                        " CCC   CCC             CCC   CCC ",
                        " CCC   CCC             CCC   CCC ",
                        " CCC   CCC   N     N   CCC   CCC ",
                        "NBBBN NBBNCCCB     BCCCNBBN NBBBN",
                        "         BCCCB     BCCCB         ",
                        "         BCCCB     BCCCB         ",
                        "         N   N     N   N         ",
                        "                                 ",
                        "         N   N     N   N         ",
                        "         BCCCB     BCCCB         ",
                        "         BCCCB     BCCCB         ",
                        "         BCCCB     BCCCB         ",
                        "         N   N     N   N         ")
                .aisle( " NNN   NNN             NNN   NNN ",
                        "                                 ",
                        "                                 ",
                        "                                 ",
                        " NNN   NNN             NNN   NNN ",
                        "                                 ",
                        "                                 ",
                        "                                 ",
                        "                                 ",
                        "                                 ",
                        " NNN   NNN             NNN   NNN ",
                        "                                 ",
                        "                                 ",
                        "                                 ",
                        " NNN   NNN   N     N   NNN   NNN ",
                        "         N   N     N   N         ",
                        "         N   N     N   N         ",
                        "                                 ",
                        "                                 ",
                        "                                 ",
                        "         N   N     N   N         ",
                        "         N   N     N   N         ",
                        "         N   N     N   N         ",
                        "                                 ")


                .where('S', selfPredicate())
                .where('N', states(getCasingState()))
                .where('B',
                        states(getCasingState2())
                                .or(metaTileEntities(MetaTileEntities.STEAM_IMPORT_BUS)
                                        .setMinGlobalLimited(1)
                                        .setMaxGlobalLimited(6))
                                .or(metaTileEntities(MetaTileEntities.STEAM_EXPORT_BUS)
                                        .setMinGlobalLimited(1)
                                        .setMaxGlobalLimited(6)))
                .where('C', blocks(Blocks.BRICK_BLOCK))
                .where('X', frames(Materials.Bronze))
                .where(' ', any())
                .build();
    }

//    protected ModularUI.Builder createUITemplate(EntityPlayer entityPlayer) {
//        return ModularUI.builder(GuiTextures.PRIMITIVE_BACKGROUND, 176, 166)
//                .shouldColor(false)
//                .widget(new LabelWidget(5, 5, getMetaFullName()))
//                .widget(new RecipeProgressWidget(recipeMapWorkable::getProgressPercent, 77, 39, 20, 15,
//                        GuiTextures.PRIMITIVE_BLAST_FURNACE_PROGRESS_BAR, ProgressWidget.MoveType.HORIZONTAL,
//                        RecipeMaps.PRIMITIVE_BLAST_FURNACE_RECIPES))
//                .bindPlayerInventory(entityPlayer.inventory, GuiTextures.PRIMITIVE_SLOT, 0);
//    }

    @Override
    public void renderMetaTileEntity(CCRenderState renderState, Matrix4 translation, IVertexOperation[] pipeline) {
        super.renderMetaTileEntity(renderState, translation, pipeline);
        getFrontOverlay().renderOrientedState(renderState, translation, pipeline, getFrontFacing(),
                recipeMapWorkable.isActive(), recipeMapWorkable.isWorkingEnabled());
    }

    @SideOnly(Side.CLIENT)
    @NotNull
    @Override
    public ICubeRenderer getFrontOverlay() {
        return Textures.PRIMITIVE_BLAST_FURNACE_OVERLAY;
    }

    @Override
    public boolean hasMaintenanceMechanics() {
        return false;
    }

    protected IBlockState getCasingState() {
        return MetaBlocks.METAL_CASING.getState(BlockMetalCasing.MetalCasingType.PRIMITIVE_BRICKS);
    }

    protected IBlockState getCasingState2() {
        return MetaBlocks.METAL_CASING.getState(BlockMetalCasing.MetalCasingType.BRONZE_BRICKS);
    }

    @Override
    public ICubeRenderer getBaseTexture(IMultiblockPart sourcePart) {
        return Textures.BRONZE_PLATED_BRICKS;
    }

    @Override
    public void addInformation(ItemStack stack, @Nullable World player, @NotNull List<String> tooltip,
                               boolean advanced) {
        super.addInformation(stack, player, tooltip, advanced);
        tooltip.add(I18n.format("gregtech.universal.tooltip.parallel", PARALLEL_LIMIT));
    }

    @SideOnly(Side.CLIENT)
    @Override
    public void randomDisplayTick() {
        if (this.isActive()) {
            VanillaParticleEffects.defaultFrontEffect(this, 0.3F, EnumParticleTypes.SMOKE_LARGE,
                    EnumParticleTypes.FLAME);
        }
    }
}
